2025-05-13 05:12:00,995 ERROR scheduler Exception in Enqueue Events for Site airplane.localhost
Traceback (most recent call last):
  File "/home/labs/frappe-bench/env/lib/python3.10/site-packages/redis/connection.py", line 1428, in get_connection
    if connection.can_read() and self.cache is None:
  File "/home/labs/frappe-bench/env/lib/python3.10/site-packages/redis/connection.py", line 570, in can_read
    return self._parser.can_read(timeout)
  File "/home/labs/frappe-bench/env/lib/python3.10/site-packages/redis/_parsers/hiredis.py", line 79, in can_read
    return self.read_from_socket(timeout=timeout, raise_on_timeout=False)
  File "/home/labs/frappe-bench/env/lib/python3.10/site-packages/redis/_parsers/hiredis.py", line 90, in read_from_socket
    raise ConnectionError(SERVER_CLOSED_CONNECTION_ERROR)
redis.exceptions.ConnectionError: Connection closed by server.

During handling of the above exception, another exception occurred:

Traceback (most recent call last):
  File "/home/labs/frappe-bench/env/lib/python3.10/site-packages/redis/connection.py", line 357, in connect
    sock = self.retry.call_with_retry(
  File "/home/labs/frappe-bench/env/lib/python3.10/site-packages/redis/retry.py", line 62, in call_with_retry
    return do()
  File "/home/labs/frappe-bench/env/lib/python3.10/site-packages/redis/connection.py", line 358, in <lambda>
    lambda: self._connect(), lambda error: self.disconnect(error)
  File "/home/labs/frappe-bench/env/lib/python3.10/site-packages/redis/connection.py", line 730, in _connect
    raise err
  File "/home/labs/frappe-bench/env/lib/python3.10/site-packages/redis/connection.py", line 718, in _connect
    sock.connect(socket_address)
ConnectionRefusedError: [Errno 111] Connection refused

During handling of the above exception, another exception occurred:

Traceback (most recent call last):
  File "/home/labs/frappe-bench/apps/frappe/frappe/utils/scheduler.py", line 120, in enqueue_events_for_site
    enqueue_events()
  File "/home/labs/frappe-bench/apps/frappe/frappe/utils/scheduler.py", line 140, in enqueue_events
    if job_type.enqueue():
  File "/home/labs/frappe-bench/apps/frappe/frappe/core/doctype/scheduled_job_type/scheduled_job_type.py", line 71, in enqueue
    if not self.is_job_in_queue():
  File "/home/labs/frappe-bench/apps/frappe/frappe/core/doctype/scheduled_job_type/scheduled_job_type.py", line 93, in is_job_in_queue
    return is_job_enqueued(self.rq_job_id)
  File "/home/labs/frappe-bench/apps/frappe/frappe/utils/background_jobs.py", line 663, in is_job_enqueued
    return get_job_status(job_id) in (JobStatus.QUEUED, JobStatus.STARTED)
  File "/home/labs/frappe-bench/apps/frappe/frappe/utils/background_jobs.py", line 668, in get_job_status
    if job := get_job(job_id):
  File "/home/labs/frappe-bench/apps/frappe/frappe/utils/background_jobs.py", line 674, in get_job
    return Job.fetch(create_job_id(job_id), connection=get_redis_conn())
  File "/home/labs/frappe-bench/env/lib/python3.10/site-packages/rq/job.py", line 670, in fetch
    job.refresh()
  File "/home/labs/frappe-bench/env/lib/python3.10/site-packages/rq/job.py", line 1033, in refresh
    data = self.connection.hgetall(self.key)
  File "/home/labs/frappe-bench/env/lib/python3.10/site-packages/redis/commands/core.py", line 4978, in hgetall
    return self.execute_command("HGETALL", name, keys=[name])
  File "/home/labs/frappe-bench/env/lib/python3.10/site-packages/redis/client.py", line 559, in execute_command
    return self._execute_command(*args, **options)
  File "/home/labs/frappe-bench/env/lib/python3.10/site-packages/redis/client.py", line 565, in _execute_command
    conn = self.connection or pool.get_connection(command_name, **options)
  File "/home/labs/frappe-bench/env/lib/python3.10/site-packages/redis/connection.py", line 1432, in get_connection
    connection.connect()
  File "/home/labs/frappe-bench/env/lib/python3.10/site-packages/redis/connection.py", line 363, in connect
    raise ConnectionError(self._error_message(e))
redis.exceptions.ConnectionError: Error 111 connecting to 127.0.0.1:11000. Connection refused.
2025-05-13 05:16:01,039 ERROR scheduler Exception in Enqueue Events for Site airplane.localhost
Traceback (most recent call last):
  File "/home/labs/frappe-bench/env/lib/python3.10/site-packages/redis/connection.py", line 357, in connect
    sock = self.retry.call_with_retry(
  File "/home/labs/frappe-bench/env/lib/python3.10/site-packages/redis/retry.py", line 62, in call_with_retry
    return do()
  File "/home/labs/frappe-bench/env/lib/python3.10/site-packages/redis/connection.py", line 358, in <lambda>
    lambda: self._connect(), lambda error: self.disconnect(error)
  File "/home/labs/frappe-bench/env/lib/python3.10/site-packages/redis/connection.py", line 730, in _connect
    raise err
  File "/home/labs/frappe-bench/env/lib/python3.10/site-packages/redis/connection.py", line 718, in _connect
    sock.connect(socket_address)
ConnectionRefusedError: [Errno 111] Connection refused

During handling of the above exception, another exception occurred:

Traceback (most recent call last):
  File "/home/labs/frappe-bench/apps/frappe/frappe/utils/scheduler.py", line 120, in enqueue_events_for_site
    enqueue_events()
  File "/home/labs/frappe-bench/apps/frappe/frappe/utils/scheduler.py", line 140, in enqueue_events
    if job_type.enqueue():
  File "/home/labs/frappe-bench/apps/frappe/frappe/core/doctype/scheduled_job_type/scheduled_job_type.py", line 71, in enqueue
    if not self.is_job_in_queue():
  File "/home/labs/frappe-bench/apps/frappe/frappe/core/doctype/scheduled_job_type/scheduled_job_type.py", line 93, in is_job_in_queue
    return is_job_enqueued(self.rq_job_id)
  File "/home/labs/frappe-bench/apps/frappe/frappe/utils/background_jobs.py", line 663, in is_job_enqueued
    return get_job_status(job_id) in (JobStatus.QUEUED, JobStatus.STARTED)
  File "/home/labs/frappe-bench/apps/frappe/frappe/utils/background_jobs.py", line 668, in get_job_status
    if job := get_job(job_id):
  File "/home/labs/frappe-bench/apps/frappe/frappe/utils/background_jobs.py", line 674, in get_job
    return Job.fetch(create_job_id(job_id), connection=get_redis_conn())
  File "/home/labs/frappe-bench/env/lib/python3.10/site-packages/rq/job.py", line 670, in fetch
    job.refresh()
  File "/home/labs/frappe-bench/env/lib/python3.10/site-packages/rq/job.py", line 1033, in refresh
    data = self.connection.hgetall(self.key)
  File "/home/labs/frappe-bench/env/lib/python3.10/site-packages/redis/commands/core.py", line 4978, in hgetall
    return self.execute_command("HGETALL", name, keys=[name])
  File "/home/labs/frappe-bench/env/lib/python3.10/site-packages/redis/client.py", line 559, in execute_command
    return self._execute_command(*args, **options)
  File "/home/labs/frappe-bench/env/lib/python3.10/site-packages/redis/client.py", line 565, in _execute_command
    conn = self.connection or pool.get_connection(command_name, **options)
  File "/home/labs/frappe-bench/env/lib/python3.10/site-packages/redis/connection.py", line 1422, in get_connection
    connection.connect()
  File "/home/labs/frappe-bench/env/lib/python3.10/site-packages/redis/connection.py", line 363, in connect
    raise ConnectionError(self._error_message(e))
redis.exceptions.ConnectionError: Error 111 connecting to 127.0.0.1:11000. Connection refused.
2025-05-13 05:20:00,141 ERROR scheduler Exception in Enqueue Events for Site airplane.localhost
Traceback (most recent call last):
  File "/home/labs/frappe-bench/env/lib/python3.10/site-packages/redis/connection.py", line 357, in connect
    sock = self.retry.call_with_retry(
  File "/home/labs/frappe-bench/env/lib/python3.10/site-packages/redis/retry.py", line 62, in call_with_retry
    return do()
  File "/home/labs/frappe-bench/env/lib/python3.10/site-packages/redis/connection.py", line 358, in <lambda>
    lambda: self._connect(), lambda error: self.disconnect(error)
  File "/home/labs/frappe-bench/env/lib/python3.10/site-packages/redis/connection.py", line 730, in _connect
    raise err
  File "/home/labs/frappe-bench/env/lib/python3.10/site-packages/redis/connection.py", line 718, in _connect
    sock.connect(socket_address)
ConnectionRefusedError: [Errno 111] Connection refused

During handling of the above exception, another exception occurred:

Traceback (most recent call last):
  File "/home/labs/frappe-bench/apps/frappe/frappe/utils/scheduler.py", line 120, in enqueue_events_for_site
    enqueue_events()
  File "/home/labs/frappe-bench/apps/frappe/frappe/utils/scheduler.py", line 140, in enqueue_events
    if job_type.enqueue():
  File "/home/labs/frappe-bench/apps/frappe/frappe/core/doctype/scheduled_job_type/scheduled_job_type.py", line 71, in enqueue
    if not self.is_job_in_queue():
  File "/home/labs/frappe-bench/apps/frappe/frappe/core/doctype/scheduled_job_type/scheduled_job_type.py", line 93, in is_job_in_queue
    return is_job_enqueued(self.rq_job_id)
  File "/home/labs/frappe-bench/apps/frappe/frappe/utils/background_jobs.py", line 663, in is_job_enqueued
    return get_job_status(job_id) in (JobStatus.QUEUED, JobStatus.STARTED)
  File "/home/labs/frappe-bench/apps/frappe/frappe/utils/background_jobs.py", line 668, in get_job_status
    if job := get_job(job_id):
  File "/home/labs/frappe-bench/apps/frappe/frappe/utils/background_jobs.py", line 674, in get_job
    return Job.fetch(create_job_id(job_id), connection=get_redis_conn())
  File "/home/labs/frappe-bench/env/lib/python3.10/site-packages/rq/job.py", line 670, in fetch
    job.refresh()
  File "/home/labs/frappe-bench/env/lib/python3.10/site-packages/rq/job.py", line 1033, in refresh
    data = self.connection.hgetall(self.key)
  File "/home/labs/frappe-bench/env/lib/python3.10/site-packages/redis/commands/core.py", line 4978, in hgetall
    return self.execute_command("HGETALL", name, keys=[name])
  File "/home/labs/frappe-bench/env/lib/python3.10/site-packages/redis/client.py", line 559, in execute_command
    return self._execute_command(*args, **options)
  File "/home/labs/frappe-bench/env/lib/python3.10/site-packages/redis/client.py", line 565, in _execute_command
    conn = self.connection or pool.get_connection(command_name, **options)
  File "/home/labs/frappe-bench/env/lib/python3.10/site-packages/redis/connection.py", line 1422, in get_connection
    connection.connect()
  File "/home/labs/frappe-bench/env/lib/python3.10/site-packages/redis/connection.py", line 363, in connect
    raise ConnectionError(self._error_message(e))
redis.exceptions.ConnectionError: Error 111 connecting to 127.0.0.1:11000. Connection refused.
2025-05-13 05:24:00,177 ERROR scheduler Exception in Enqueue Events for Site airplane.localhost
Traceback (most recent call last):
  File "/home/labs/frappe-bench/env/lib/python3.10/site-packages/redis/connection.py", line 357, in connect
    sock = self.retry.call_with_retry(
  File "/home/labs/frappe-bench/env/lib/python3.10/site-packages/redis/retry.py", line 62, in call_with_retry
    return do()
  File "/home/labs/frappe-bench/env/lib/python3.10/site-packages/redis/connection.py", line 358, in <lambda>
    lambda: self._connect(), lambda error: self.disconnect(error)
  File "/home/labs/frappe-bench/env/lib/python3.10/site-packages/redis/connection.py", line 730, in _connect
    raise err
  File "/home/labs/frappe-bench/env/lib/python3.10/site-packages/redis/connection.py", line 718, in _connect
    sock.connect(socket_address)
ConnectionRefusedError: [Errno 111] Connection refused

During handling of the above exception, another exception occurred:

Traceback (most recent call last):
  File "/home/labs/frappe-bench/apps/frappe/frappe/utils/scheduler.py", line 120, in enqueue_events_for_site
    enqueue_events()
  File "/home/labs/frappe-bench/apps/frappe/frappe/utils/scheduler.py", line 140, in enqueue_events
    if job_type.enqueue():
  File "/home/labs/frappe-bench/apps/frappe/frappe/core/doctype/scheduled_job_type/scheduled_job_type.py", line 71, in enqueue
    if not self.is_job_in_queue():
  File "/home/labs/frappe-bench/apps/frappe/frappe/core/doctype/scheduled_job_type/scheduled_job_type.py", line 93, in is_job_in_queue
    return is_job_enqueued(self.rq_job_id)
  File "/home/labs/frappe-bench/apps/frappe/frappe/utils/background_jobs.py", line 663, in is_job_enqueued
    return get_job_status(job_id) in (JobStatus.QUEUED, JobStatus.STARTED)
  File "/home/labs/frappe-bench/apps/frappe/frappe/utils/background_jobs.py", line 668, in get_job_status
    if job := get_job(job_id):
  File "/home/labs/frappe-bench/apps/frappe/frappe/utils/background_jobs.py", line 674, in get_job
    return Job.fetch(create_job_id(job_id), connection=get_redis_conn())
  File "/home/labs/frappe-bench/env/lib/python3.10/site-packages/rq/job.py", line 670, in fetch
    job.refresh()
  File "/home/labs/frappe-bench/env/lib/python3.10/site-packages/rq/job.py", line 1033, in refresh
    data = self.connection.hgetall(self.key)
  File "/home/labs/frappe-bench/env/lib/python3.10/site-packages/redis/commands/core.py", line 4978, in hgetall
    return self.execute_command("HGETALL", name, keys=[name])
  File "/home/labs/frappe-bench/env/lib/python3.10/site-packages/redis/client.py", line 559, in execute_command
    return self._execute_command(*args, **options)
  File "/home/labs/frappe-bench/env/lib/python3.10/site-packages/redis/client.py", line 565, in _execute_command
    conn = self.connection or pool.get_connection(command_name, **options)
  File "/home/labs/frappe-bench/env/lib/python3.10/site-packages/redis/connection.py", line 1422, in get_connection
    connection.connect()
  File "/home/labs/frappe-bench/env/lib/python3.10/site-packages/redis/connection.py", line 363, in connect
    raise ConnectionError(self._error_message(e))
redis.exceptions.ConnectionError: Error 111 connecting to 127.0.0.1:11000. Connection refused.
2025-05-13 05:28:00,253 ERROR scheduler Exception in Enqueue Events for Site airplane.localhost
Traceback (most recent call last):
  File "/home/labs/frappe-bench/env/lib/python3.10/site-packages/redis/connection.py", line 357, in connect
    sock = self.retry.call_with_retry(
  File "/home/labs/frappe-bench/env/lib/python3.10/site-packages/redis/retry.py", line 62, in call_with_retry
    return do()
  File "/home/labs/frappe-bench/env/lib/python3.10/site-packages/redis/connection.py", line 358, in <lambda>
    lambda: self._connect(), lambda error: self.disconnect(error)
  File "/home/labs/frappe-bench/env/lib/python3.10/site-packages/redis/connection.py", line 730, in _connect
    raise err
  File "/home/labs/frappe-bench/env/lib/python3.10/site-packages/redis/connection.py", line 718, in _connect
    sock.connect(socket_address)
ConnectionRefusedError: [Errno 111] Connection refused

During handling of the above exception, another exception occurred:

Traceback (most recent call last):
  File "/home/labs/frappe-bench/apps/frappe/frappe/utils/scheduler.py", line 120, in enqueue_events_for_site
    enqueue_events()
  File "/home/labs/frappe-bench/apps/frappe/frappe/utils/scheduler.py", line 140, in enqueue_events
    if job_type.enqueue():
  File "/home/labs/frappe-bench/apps/frappe/frappe/core/doctype/scheduled_job_type/scheduled_job_type.py", line 71, in enqueue
    if not self.is_job_in_queue():
  File "/home/labs/frappe-bench/apps/frappe/frappe/core/doctype/scheduled_job_type/scheduled_job_type.py", line 93, in is_job_in_queue
    return is_job_enqueued(self.rq_job_id)
  File "/home/labs/frappe-bench/apps/frappe/frappe/utils/background_jobs.py", line 663, in is_job_enqueued
    return get_job_status(job_id) in (JobStatus.QUEUED, JobStatus.STARTED)
  File "/home/labs/frappe-bench/apps/frappe/frappe/utils/background_jobs.py", line 668, in get_job_status
    if job := get_job(job_id):
  File "/home/labs/frappe-bench/apps/frappe/frappe/utils/background_jobs.py", line 674, in get_job
    return Job.fetch(create_job_id(job_id), connection=get_redis_conn())
  File "/home/labs/frappe-bench/env/lib/python3.10/site-packages/rq/job.py", line 670, in fetch
    job.refresh()
  File "/home/labs/frappe-bench/env/lib/python3.10/site-packages/rq/job.py", line 1033, in refresh
    data = self.connection.hgetall(self.key)
  File "/home/labs/frappe-bench/env/lib/python3.10/site-packages/redis/commands/core.py", line 4978, in hgetall
    return self.execute_command("HGETALL", name, keys=[name])
  File "/home/labs/frappe-bench/env/lib/python3.10/site-packages/redis/client.py", line 559, in execute_command
    return self._execute_command(*args, **options)
  File "/home/labs/frappe-bench/env/lib/python3.10/site-packages/redis/client.py", line 565, in _execute_command
    conn = self.connection or pool.get_connection(command_name, **options)
  File "/home/labs/frappe-bench/env/lib/python3.10/site-packages/redis/connection.py", line 1422, in get_connection
    connection.connect()
  File "/home/labs/frappe-bench/env/lib/python3.10/site-packages/redis/connection.py", line 363, in connect
    raise ConnectionError(self._error_message(e))
redis.exceptions.ConnectionError: Error 111 connecting to 127.0.0.1:11000. Connection refused.
2025-05-13 05:32:00,341 ERROR scheduler Exception in Enqueue Events for Site airplane.localhost
Traceback (most recent call last):
  File "/home/labs/frappe-bench/env/lib/python3.10/site-packages/redis/connection.py", line 357, in connect
    sock = self.retry.call_with_retry(
  File "/home/labs/frappe-bench/env/lib/python3.10/site-packages/redis/retry.py", line 62, in call_with_retry
    return do()
  File "/home/labs/frappe-bench/env/lib/python3.10/site-packages/redis/connection.py", line 358, in <lambda>
    lambda: self._connect(), lambda error: self.disconnect(error)
  File "/home/labs/frappe-bench/env/lib/python3.10/site-packages/redis/connection.py", line 730, in _connect
    raise err
  File "/home/labs/frappe-bench/env/lib/python3.10/site-packages/redis/connection.py", line 718, in _connect
    sock.connect(socket_address)
ConnectionRefusedError: [Errno 111] Connection refused

During handling of the above exception, another exception occurred:

Traceback (most recent call last):
  File "/home/labs/frappe-bench/apps/frappe/frappe/utils/scheduler.py", line 120, in enqueue_events_for_site
    enqueue_events()
  File "/home/labs/frappe-bench/apps/frappe/frappe/utils/scheduler.py", line 140, in enqueue_events
    if job_type.enqueue():
  File "/home/labs/frappe-bench/apps/frappe/frappe/core/doctype/scheduled_job_type/scheduled_job_type.py", line 71, in enqueue
    if not self.is_job_in_queue():
  File "/home/labs/frappe-bench/apps/frappe/frappe/core/doctype/scheduled_job_type/scheduled_job_type.py", line 93, in is_job_in_queue
    return is_job_enqueued(self.rq_job_id)
  File "/home/labs/frappe-bench/apps/frappe/frappe/utils/background_jobs.py", line 663, in is_job_enqueued
    return get_job_status(job_id) in (JobStatus.QUEUED, JobStatus.STARTED)
  File "/home/labs/frappe-bench/apps/frappe/frappe/utils/background_jobs.py", line 668, in get_job_status
    if job := get_job(job_id):
  File "/home/labs/frappe-bench/apps/frappe/frappe/utils/background_jobs.py", line 674, in get_job
    return Job.fetch(create_job_id(job_id), connection=get_redis_conn())
  File "/home/labs/frappe-bench/env/lib/python3.10/site-packages/rq/job.py", line 670, in fetch
    job.refresh()
  File "/home/labs/frappe-bench/env/lib/python3.10/site-packages/rq/job.py", line 1033, in refresh
    data = self.connection.hgetall(self.key)
  File "/home/labs/frappe-bench/env/lib/python3.10/site-packages/redis/commands/core.py", line 4978, in hgetall
    return self.execute_command("HGETALL", name, keys=[name])
  File "/home/labs/frappe-bench/env/lib/python3.10/site-packages/redis/client.py", line 559, in execute_command
    return self._execute_command(*args, **options)
  File "/home/labs/frappe-bench/env/lib/python3.10/site-packages/redis/client.py", line 565, in _execute_command
    conn = self.connection or pool.get_connection(command_name, **options)
  File "/home/labs/frappe-bench/env/lib/python3.10/site-packages/redis/connection.py", line 1422, in get_connection
    connection.connect()
  File "/home/labs/frappe-bench/env/lib/python3.10/site-packages/redis/connection.py", line 363, in connect
    raise ConnectionError(self._error_message(e))
redis.exceptions.ConnectionError: Error 111 connecting to 127.0.0.1:11000. Connection refused.
2025-05-13 05:36:00,450 ERROR scheduler Exception in Enqueue Events for Site airplane.localhost
Traceback (most recent call last):
  File "/home/labs/frappe-bench/env/lib/python3.10/site-packages/redis/connection.py", line 357, in connect
    sock = self.retry.call_with_retry(
  File "/home/labs/frappe-bench/env/lib/python3.10/site-packages/redis/retry.py", line 62, in call_with_retry
    return do()
  File "/home/labs/frappe-bench/env/lib/python3.10/site-packages/redis/connection.py", line 358, in <lambda>
    lambda: self._connect(), lambda error: self.disconnect(error)
  File "/home/labs/frappe-bench/env/lib/python3.10/site-packages/redis/connection.py", line 730, in _connect
    raise err
  File "/home/labs/frappe-bench/env/lib/python3.10/site-packages/redis/connection.py", line 718, in _connect
    sock.connect(socket_address)
ConnectionRefusedError: [Errno 111] Connection refused

During handling of the above exception, another exception occurred:

Traceback (most recent call last):
  File "/home/labs/frappe-bench/apps/frappe/frappe/utils/scheduler.py", line 120, in enqueue_events_for_site
    enqueue_events()
  File "/home/labs/frappe-bench/apps/frappe/frappe/utils/scheduler.py", line 140, in enqueue_events
    if job_type.enqueue():
  File "/home/labs/frappe-bench/apps/frappe/frappe/core/doctype/scheduled_job_type/scheduled_job_type.py", line 71, in enqueue
    if not self.is_job_in_queue():
  File "/home/labs/frappe-bench/apps/frappe/frappe/core/doctype/scheduled_job_type/scheduled_job_type.py", line 93, in is_job_in_queue
    return is_job_enqueued(self.rq_job_id)
  File "/home/labs/frappe-bench/apps/frappe/frappe/utils/background_jobs.py", line 663, in is_job_enqueued
    return get_job_status(job_id) in (JobStatus.QUEUED, JobStatus.STARTED)
  File "/home/labs/frappe-bench/apps/frappe/frappe/utils/background_jobs.py", line 668, in get_job_status
    if job := get_job(job_id):
  File "/home/labs/frappe-bench/apps/frappe/frappe/utils/background_jobs.py", line 674, in get_job
    return Job.fetch(create_job_id(job_id), connection=get_redis_conn())
  File "/home/labs/frappe-bench/env/lib/python3.10/site-packages/rq/job.py", line 670, in fetch
    job.refresh()
  File "/home/labs/frappe-bench/env/lib/python3.10/site-packages/rq/job.py", line 1033, in refresh
    data = self.connection.hgetall(self.key)
  File "/home/labs/frappe-bench/env/lib/python3.10/site-packages/redis/commands/core.py", line 4978, in hgetall
    return self.execute_command("HGETALL", name, keys=[name])
  File "/home/labs/frappe-bench/env/lib/python3.10/site-packages/redis/client.py", line 559, in execute_command
    return self._execute_command(*args, **options)
  File "/home/labs/frappe-bench/env/lib/python3.10/site-packages/redis/client.py", line 565, in _execute_command
    conn = self.connection or pool.get_connection(command_name, **options)
  File "/home/labs/frappe-bench/env/lib/python3.10/site-packages/redis/connection.py", line 1422, in get_connection
    connection.connect()
  File "/home/labs/frappe-bench/env/lib/python3.10/site-packages/redis/connection.py", line 363, in connect
    raise ConnectionError(self._error_message(e))
redis.exceptions.ConnectionError: Error 111 connecting to 127.0.0.1:11000. Connection refused.
2025-05-13 05:40:00,552 ERROR scheduler Exception in Enqueue Events for Site airplane.localhost
Traceback (most recent call last):
  File "/home/labs/frappe-bench/env/lib/python3.10/site-packages/redis/connection.py", line 357, in connect
    sock = self.retry.call_with_retry(
  File "/home/labs/frappe-bench/env/lib/python3.10/site-packages/redis/retry.py", line 62, in call_with_retry
    return do()
  File "/home/labs/frappe-bench/env/lib/python3.10/site-packages/redis/connection.py", line 358, in <lambda>
    lambda: self._connect(), lambda error: self.disconnect(error)
  File "/home/labs/frappe-bench/env/lib/python3.10/site-packages/redis/connection.py", line 730, in _connect
    raise err
  File "/home/labs/frappe-bench/env/lib/python3.10/site-packages/redis/connection.py", line 718, in _connect
    sock.connect(socket_address)
ConnectionRefusedError: [Errno 111] Connection refused

During handling of the above exception, another exception occurred:

Traceback (most recent call last):
  File "/home/labs/frappe-bench/apps/frappe/frappe/utils/scheduler.py", line 120, in enqueue_events_for_site
    enqueue_events()
  File "/home/labs/frappe-bench/apps/frappe/frappe/utils/scheduler.py", line 140, in enqueue_events
    if job_type.enqueue():
  File "/home/labs/frappe-bench/apps/frappe/frappe/core/doctype/scheduled_job_type/scheduled_job_type.py", line 71, in enqueue
    if not self.is_job_in_queue():
  File "/home/labs/frappe-bench/apps/frappe/frappe/core/doctype/scheduled_job_type/scheduled_job_type.py", line 93, in is_job_in_queue
    return is_job_enqueued(self.rq_job_id)
  File "/home/labs/frappe-bench/apps/frappe/frappe/utils/background_jobs.py", line 663, in is_job_enqueued
    return get_job_status(job_id) in (JobStatus.QUEUED, JobStatus.STARTED)
  File "/home/labs/frappe-bench/apps/frappe/frappe/utils/background_jobs.py", line 668, in get_job_status
    if job := get_job(job_id):
  File "/home/labs/frappe-bench/apps/frappe/frappe/utils/background_jobs.py", line 674, in get_job
    return Job.fetch(create_job_id(job_id), connection=get_redis_conn())
  File "/home/labs/frappe-bench/env/lib/python3.10/site-packages/rq/job.py", line 670, in fetch
    job.refresh()
  File "/home/labs/frappe-bench/env/lib/python3.10/site-packages/rq/job.py", line 1033, in refresh
    data = self.connection.hgetall(self.key)
  File "/home/labs/frappe-bench/env/lib/python3.10/site-packages/redis/commands/core.py", line 4978, in hgetall
    return self.execute_command("HGETALL", name, keys=[name])
  File "/home/labs/frappe-bench/env/lib/python3.10/site-packages/redis/client.py", line 559, in execute_command
    return self._execute_command(*args, **options)
  File "/home/labs/frappe-bench/env/lib/python3.10/site-packages/redis/client.py", line 565, in _execute_command
    conn = self.connection or pool.get_connection(command_name, **options)
  File "/home/labs/frappe-bench/env/lib/python3.10/site-packages/redis/connection.py", line 1422, in get_connection
    connection.connect()
  File "/home/labs/frappe-bench/env/lib/python3.10/site-packages/redis/connection.py", line 363, in connect
    raise ConnectionError(self._error_message(e))
redis.exceptions.ConnectionError: Error 111 connecting to 127.0.0.1:11000. Connection refused.
2025-05-13 05:44:00,604 ERROR scheduler Exception in Enqueue Events for Site airplane.localhost
Traceback (most recent call last):
  File "/home/labs/frappe-bench/env/lib/python3.10/site-packages/redis/connection.py", line 357, in connect
    sock = self.retry.call_with_retry(
  File "/home/labs/frappe-bench/env/lib/python3.10/site-packages/redis/retry.py", line 62, in call_with_retry
    return do()
  File "/home/labs/frappe-bench/env/lib/python3.10/site-packages/redis/connection.py", line 358, in <lambda>
    lambda: self._connect(), lambda error: self.disconnect(error)
  File "/home/labs/frappe-bench/env/lib/python3.10/site-packages/redis/connection.py", line 730, in _connect
    raise err
  File "/home/labs/frappe-bench/env/lib/python3.10/site-packages/redis/connection.py", line 718, in _connect
    sock.connect(socket_address)
ConnectionRefusedError: [Errno 111] Connection refused

During handling of the above exception, another exception occurred:

Traceback (most recent call last):
  File "/home/labs/frappe-bench/apps/frappe/frappe/utils/scheduler.py", line 120, in enqueue_events_for_site
    enqueue_events()
  File "/home/labs/frappe-bench/apps/frappe/frappe/utils/scheduler.py", line 140, in enqueue_events
    if job_type.enqueue():
  File "/home/labs/frappe-bench/apps/frappe/frappe/core/doctype/scheduled_job_type/scheduled_job_type.py", line 71, in enqueue
    if not self.is_job_in_queue():
  File "/home/labs/frappe-bench/apps/frappe/frappe/core/doctype/scheduled_job_type/scheduled_job_type.py", line 93, in is_job_in_queue
    return is_job_enqueued(self.rq_job_id)
  File "/home/labs/frappe-bench/apps/frappe/frappe/utils/background_jobs.py", line 663, in is_job_enqueued
    return get_job_status(job_id) in (JobStatus.QUEUED, JobStatus.STARTED)
  File "/home/labs/frappe-bench/apps/frappe/frappe/utils/background_jobs.py", line 668, in get_job_status
    if job := get_job(job_id):
  File "/home/labs/frappe-bench/apps/frappe/frappe/utils/background_jobs.py", line 674, in get_job
    return Job.fetch(create_job_id(job_id), connection=get_redis_conn())
  File "/home/labs/frappe-bench/env/lib/python3.10/site-packages/rq/job.py", line 670, in fetch
    job.refresh()
  File "/home/labs/frappe-bench/env/lib/python3.10/site-packages/rq/job.py", line 1033, in refresh
    data = self.connection.hgetall(self.key)
  File "/home/labs/frappe-bench/env/lib/python3.10/site-packages/redis/commands/core.py", line 4978, in hgetall
    return self.execute_command("HGETALL", name, keys=[name])
  File "/home/labs/frappe-bench/env/lib/python3.10/site-packages/redis/client.py", line 559, in execute_command
    return self._execute_command(*args, **options)
  File "/home/labs/frappe-bench/env/lib/python3.10/site-packages/redis/client.py", line 565, in _execute_command
    conn = self.connection or pool.get_connection(command_name, **options)
  File "/home/labs/frappe-bench/env/lib/python3.10/site-packages/redis/connection.py", line 1422, in get_connection
    connection.connect()
  File "/home/labs/frappe-bench/env/lib/python3.10/site-packages/redis/connection.py", line 363, in connect
    raise ConnectionError(self._error_message(e))
redis.exceptions.ConnectionError: Error 111 connecting to 127.0.0.1:11000. Connection refused.
2025-05-13 05:48:00,673 ERROR scheduler Exception in Enqueue Events for Site airplane.localhost
Traceback (most recent call last):
  File "/home/labs/frappe-bench/env/lib/python3.10/site-packages/redis/connection.py", line 357, in connect
    sock = self.retry.call_with_retry(
  File "/home/labs/frappe-bench/env/lib/python3.10/site-packages/redis/retry.py", line 62, in call_with_retry
    return do()
  File "/home/labs/frappe-bench/env/lib/python3.10/site-packages/redis/connection.py", line 358, in <lambda>
    lambda: self._connect(), lambda error: self.disconnect(error)
  File "/home/labs/frappe-bench/env/lib/python3.10/site-packages/redis/connection.py", line 730, in _connect
    raise err
  File "/home/labs/frappe-bench/env/lib/python3.10/site-packages/redis/connection.py", line 718, in _connect
    sock.connect(socket_address)
ConnectionRefusedError: [Errno 111] Connection refused

During handling of the above exception, another exception occurred:

Traceback (most recent call last):
  File "/home/labs/frappe-bench/apps/frappe/frappe/utils/scheduler.py", line 120, in enqueue_events_for_site
    enqueue_events()
  File "/home/labs/frappe-bench/apps/frappe/frappe/utils/scheduler.py", line 140, in enqueue_events
    if job_type.enqueue():
  File "/home/labs/frappe-bench/apps/frappe/frappe/core/doctype/scheduled_job_type/scheduled_job_type.py", line 71, in enqueue
    if not self.is_job_in_queue():
  File "/home/labs/frappe-bench/apps/frappe/frappe/core/doctype/scheduled_job_type/scheduled_job_type.py", line 93, in is_job_in_queue
    return is_job_enqueued(self.rq_job_id)
  File "/home/labs/frappe-bench/apps/frappe/frappe/utils/background_jobs.py", line 663, in is_job_enqueued
    return get_job_status(job_id) in (JobStatus.QUEUED, JobStatus.STARTED)
  File "/home/labs/frappe-bench/apps/frappe/frappe/utils/background_jobs.py", line 668, in get_job_status
    if job := get_job(job_id):
  File "/home/labs/frappe-bench/apps/frappe/frappe/utils/background_jobs.py", line 674, in get_job
    return Job.fetch(create_job_id(job_id), connection=get_redis_conn())
  File "/home/labs/frappe-bench/env/lib/python3.10/site-packages/rq/job.py", line 670, in fetch
    job.refresh()
  File "/home/labs/frappe-bench/env/lib/python3.10/site-packages/rq/job.py", line 1033, in refresh
    data = self.connection.hgetall(self.key)
  File "/home/labs/frappe-bench/env/lib/python3.10/site-packages/redis/commands/core.py", line 4978, in hgetall
    return self.execute_command("HGETALL", name, keys=[name])
  File "/home/labs/frappe-bench/env/lib/python3.10/site-packages/redis/client.py", line 559, in execute_command
    return self._execute_command(*args, **options)
  File "/home/labs/frappe-bench/env/lib/python3.10/site-packages/redis/client.py", line 565, in _execute_command
    conn = self.connection or pool.get_connection(command_name, **options)
  File "/home/labs/frappe-bench/env/lib/python3.10/site-packages/redis/connection.py", line 1422, in get_connection
    connection.connect()
  File "/home/labs/frappe-bench/env/lib/python3.10/site-packages/redis/connection.py", line 363, in connect
    raise ConnectionError(self._error_message(e))
redis.exceptions.ConnectionError: Error 111 connecting to 127.0.0.1:11000. Connection refused.
2025-05-13 05:52:00,749 ERROR scheduler Exception in Enqueue Events for Site airplane.localhost
Traceback (most recent call last):
  File "/home/labs/frappe-bench/env/lib/python3.10/site-packages/redis/connection.py", line 357, in connect
    sock = self.retry.call_with_retry(
  File "/home/labs/frappe-bench/env/lib/python3.10/site-packages/redis/retry.py", line 62, in call_with_retry
    return do()
  File "/home/labs/frappe-bench/env/lib/python3.10/site-packages/redis/connection.py", line 358, in <lambda>
    lambda: self._connect(), lambda error: self.disconnect(error)
  File "/home/labs/frappe-bench/env/lib/python3.10/site-packages/redis/connection.py", line 730, in _connect
    raise err
  File "/home/labs/frappe-bench/env/lib/python3.10/site-packages/redis/connection.py", line 718, in _connect
    sock.connect(socket_address)
ConnectionRefusedError: [Errno 111] Connection refused

During handling of the above exception, another exception occurred:

Traceback (most recent call last):
  File "/home/labs/frappe-bench/apps/frappe/frappe/utils/scheduler.py", line 120, in enqueue_events_for_site
    enqueue_events()
  File "/home/labs/frappe-bench/apps/frappe/frappe/utils/scheduler.py", line 140, in enqueue_events
    if job_type.enqueue():
  File "/home/labs/frappe-bench/apps/frappe/frappe/core/doctype/scheduled_job_type/scheduled_job_type.py", line 71, in enqueue
    if not self.is_job_in_queue():
  File "/home/labs/frappe-bench/apps/frappe/frappe/core/doctype/scheduled_job_type/scheduled_job_type.py", line 93, in is_job_in_queue
    return is_job_enqueued(self.rq_job_id)
  File "/home/labs/frappe-bench/apps/frappe/frappe/utils/background_jobs.py", line 663, in is_job_enqueued
    return get_job_status(job_id) in (JobStatus.QUEUED, JobStatus.STARTED)
  File "/home/labs/frappe-bench/apps/frappe/frappe/utils/background_jobs.py", line 668, in get_job_status
    if job := get_job(job_id):
  File "/home/labs/frappe-bench/apps/frappe/frappe/utils/background_jobs.py", line 674, in get_job
    return Job.fetch(create_job_id(job_id), connection=get_redis_conn())
  File "/home/labs/frappe-bench/env/lib/python3.10/site-packages/rq/job.py", line 670, in fetch
    job.refresh()
  File "/home/labs/frappe-bench/env/lib/python3.10/site-packages/rq/job.py", line 1033, in refresh
    data = self.connection.hgetall(self.key)
  File "/home/labs/frappe-bench/env/lib/python3.10/site-packages/redis/commands/core.py", line 4978, in hgetall
    return self.execute_command("HGETALL", name, keys=[name])
  File "/home/labs/frappe-bench/env/lib/python3.10/site-packages/redis/client.py", line 559, in execute_command
    return self._execute_command(*args, **options)
  File "/home/labs/frappe-bench/env/lib/python3.10/site-packages/redis/client.py", line 565, in _execute_command
    conn = self.connection or pool.get_connection(command_name, **options)
  File "/home/labs/frappe-bench/env/lib/python3.10/site-packages/redis/connection.py", line 1422, in get_connection
    connection.connect()
  File "/home/labs/frappe-bench/env/lib/python3.10/site-packages/redis/connection.py", line 363, in connect
    raise ConnectionError(self._error_message(e))
redis.exceptions.ConnectionError: Error 111 connecting to 127.0.0.1:11000. Connection refused.
2025-05-13 05:56:00,794 ERROR scheduler Exception in Enqueue Events for Site airplane.localhost
Traceback (most recent call last):
  File "/home/labs/frappe-bench/env/lib/python3.10/site-packages/redis/connection.py", line 357, in connect
    sock = self.retry.call_with_retry(
  File "/home/labs/frappe-bench/env/lib/python3.10/site-packages/redis/retry.py", line 62, in call_with_retry
    return do()
  File "/home/labs/frappe-bench/env/lib/python3.10/site-packages/redis/connection.py", line 358, in <lambda>
    lambda: self._connect(), lambda error: self.disconnect(error)
  File "/home/labs/frappe-bench/env/lib/python3.10/site-packages/redis/connection.py", line 730, in _connect
    raise err
  File "/home/labs/frappe-bench/env/lib/python3.10/site-packages/redis/connection.py", line 718, in _connect
    sock.connect(socket_address)
ConnectionRefusedError: [Errno 111] Connection refused

During handling of the above exception, another exception occurred:

Traceback (most recent call last):
  File "/home/labs/frappe-bench/apps/frappe/frappe/utils/scheduler.py", line 120, in enqueue_events_for_site
    enqueue_events()
  File "/home/labs/frappe-bench/apps/frappe/frappe/utils/scheduler.py", line 140, in enqueue_events
    if job_type.enqueue():
  File "/home/labs/frappe-bench/apps/frappe/frappe/core/doctype/scheduled_job_type/scheduled_job_type.py", line 71, in enqueue
    if not self.is_job_in_queue():
  File "/home/labs/frappe-bench/apps/frappe/frappe/core/doctype/scheduled_job_type/scheduled_job_type.py", line 93, in is_job_in_queue
    return is_job_enqueued(self.rq_job_id)
  File "/home/labs/frappe-bench/apps/frappe/frappe/utils/background_jobs.py", line 663, in is_job_enqueued
    return get_job_status(job_id) in (JobStatus.QUEUED, JobStatus.STARTED)
  File "/home/labs/frappe-bench/apps/frappe/frappe/utils/background_jobs.py", line 668, in get_job_status
    if job := get_job(job_id):
  File "/home/labs/frappe-bench/apps/frappe/frappe/utils/background_jobs.py", line 674, in get_job
    return Job.fetch(create_job_id(job_id), connection=get_redis_conn())
  File "/home/labs/frappe-bench/env/lib/python3.10/site-packages/rq/job.py", line 670, in fetch
    job.refresh()
  File "/home/labs/frappe-bench/env/lib/python3.10/site-packages/rq/job.py", line 1033, in refresh
    data = self.connection.hgetall(self.key)
  File "/home/labs/frappe-bench/env/lib/python3.10/site-packages/redis/commands/core.py", line 4978, in hgetall
    return self.execute_command("HGETALL", name, keys=[name])
  File "/home/labs/frappe-bench/env/lib/python3.10/site-packages/redis/client.py", line 559, in execute_command
    return self._execute_command(*args, **options)
  File "/home/labs/frappe-bench/env/lib/python3.10/site-packages/redis/client.py", line 565, in _execute_command
    conn = self.connection or pool.get_connection(command_name, **options)
  File "/home/labs/frappe-bench/env/lib/python3.10/site-packages/redis/connection.py", line 1422, in get_connection
    connection.connect()
  File "/home/labs/frappe-bench/env/lib/python3.10/site-packages/redis/connection.py", line 363, in connect
    raise ConnectionError(self._error_message(e))
redis.exceptions.ConnectionError: Error 111 connecting to 127.0.0.1:11000. Connection refused.
2025-05-13 06:00:00,901 ERROR scheduler Exception in Enqueue Events for Site airplane.localhost
Traceback (most recent call last):
  File "/home/labs/frappe-bench/env/lib/python3.10/site-packages/redis/connection.py", line 357, in connect
    sock = self.retry.call_with_retry(
  File "/home/labs/frappe-bench/env/lib/python3.10/site-packages/redis/retry.py", line 62, in call_with_retry
    return do()
  File "/home/labs/frappe-bench/env/lib/python3.10/site-packages/redis/connection.py", line 358, in <lambda>
    lambda: self._connect(), lambda error: self.disconnect(error)
  File "/home/labs/frappe-bench/env/lib/python3.10/site-packages/redis/connection.py", line 730, in _connect
    raise err
  File "/home/labs/frappe-bench/env/lib/python3.10/site-packages/redis/connection.py", line 718, in _connect
    sock.connect(socket_address)
ConnectionRefusedError: [Errno 111] Connection refused

During handling of the above exception, another exception occurred:

Traceback (most recent call last):
  File "/home/labs/frappe-bench/apps/frappe/frappe/utils/scheduler.py", line 120, in enqueue_events_for_site
    enqueue_events()
  File "/home/labs/frappe-bench/apps/frappe/frappe/utils/scheduler.py", line 140, in enqueue_events
    if job_type.enqueue():
  File "/home/labs/frappe-bench/apps/frappe/frappe/core/doctype/scheduled_job_type/scheduled_job_type.py", line 71, in enqueue
    if not self.is_job_in_queue():
  File "/home/labs/frappe-bench/apps/frappe/frappe/core/doctype/scheduled_job_type/scheduled_job_type.py", line 93, in is_job_in_queue
    return is_job_enqueued(self.rq_job_id)
  File "/home/labs/frappe-bench/apps/frappe/frappe/utils/background_jobs.py", line 663, in is_job_enqueued
    return get_job_status(job_id) in (JobStatus.QUEUED, JobStatus.STARTED)
  File "/home/labs/frappe-bench/apps/frappe/frappe/utils/background_jobs.py", line 668, in get_job_status
    if job := get_job(job_id):
  File "/home/labs/frappe-bench/apps/frappe/frappe/utils/background_jobs.py", line 674, in get_job
    return Job.fetch(create_job_id(job_id), connection=get_redis_conn())
  File "/home/labs/frappe-bench/env/lib/python3.10/site-packages/rq/job.py", line 670, in fetch
    job.refresh()
  File "/home/labs/frappe-bench/env/lib/python3.10/site-packages/rq/job.py", line 1033, in refresh
    data = self.connection.hgetall(self.key)
  File "/home/labs/frappe-bench/env/lib/python3.10/site-packages/redis/commands/core.py", line 4978, in hgetall
    return self.execute_command("HGETALL", name, keys=[name])
  File "/home/labs/frappe-bench/env/lib/python3.10/site-packages/redis/client.py", line 559, in execute_command
    return self._execute_command(*args, **options)
  File "/home/labs/frappe-bench/env/lib/python3.10/site-packages/redis/client.py", line 565, in _execute_command
    conn = self.connection or pool.get_connection(command_name, **options)
  File "/home/labs/frappe-bench/env/lib/python3.10/site-packages/redis/connection.py", line 1422, in get_connection
    connection.connect()
  File "/home/labs/frappe-bench/env/lib/python3.10/site-packages/redis/connection.py", line 363, in connect
    raise ConnectionError(self._error_message(e))
redis.exceptions.ConnectionError: Error 111 connecting to 127.0.0.1:11000. Connection refused.
2025-05-13 06:04:01,006 ERROR scheduler Exception in Enqueue Events for Site airplane.localhost
Traceback (most recent call last):
  File "/home/labs/frappe-bench/env/lib/python3.10/site-packages/redis/connection.py", line 357, in connect
    sock = self.retry.call_with_retry(
  File "/home/labs/frappe-bench/env/lib/python3.10/site-packages/redis/retry.py", line 62, in call_with_retry
    return do()
  File "/home/labs/frappe-bench/env/lib/python3.10/site-packages/redis/connection.py", line 358, in <lambda>
    lambda: self._connect(), lambda error: self.disconnect(error)
  File "/home/labs/frappe-bench/env/lib/python3.10/site-packages/redis/connection.py", line 730, in _connect
    raise err
  File "/home/labs/frappe-bench/env/lib/python3.10/site-packages/redis/connection.py", line 718, in _connect
    sock.connect(socket_address)
ConnectionRefusedError: [Errno 111] Connection refused

During handling of the above exception, another exception occurred:

Traceback (most recent call last):
  File "/home/labs/frappe-bench/apps/frappe/frappe/utils/scheduler.py", line 120, in enqueue_events_for_site
    enqueue_events()
  File "/home/labs/frappe-bench/apps/frappe/frappe/utils/scheduler.py", line 140, in enqueue_events
    if job_type.enqueue():
  File "/home/labs/frappe-bench/apps/frappe/frappe/core/doctype/scheduled_job_type/scheduled_job_type.py", line 71, in enqueue
    if not self.is_job_in_queue():
  File "/home/labs/frappe-bench/apps/frappe/frappe/core/doctype/scheduled_job_type/scheduled_job_type.py", line 93, in is_job_in_queue
    return is_job_enqueued(self.rq_job_id)
  File "/home/labs/frappe-bench/apps/frappe/frappe/utils/background_jobs.py", line 663, in is_job_enqueued
    return get_job_status(job_id) in (JobStatus.QUEUED, JobStatus.STARTED)
  File "/home/labs/frappe-bench/apps/frappe/frappe/utils/background_jobs.py", line 668, in get_job_status
    if job := get_job(job_id):
  File "/home/labs/frappe-bench/apps/frappe/frappe/utils/background_jobs.py", line 674, in get_job
    return Job.fetch(create_job_id(job_id), connection=get_redis_conn())
  File "/home/labs/frappe-bench/env/lib/python3.10/site-packages/rq/job.py", line 670, in fetch
    job.refresh()
  File "/home/labs/frappe-bench/env/lib/python3.10/site-packages/rq/job.py", line 1033, in refresh
    data = self.connection.hgetall(self.key)
  File "/home/labs/frappe-bench/env/lib/python3.10/site-packages/redis/commands/core.py", line 4978, in hgetall
    return self.execute_command("HGETALL", name, keys=[name])
  File "/home/labs/frappe-bench/env/lib/python3.10/site-packages/redis/client.py", line 559, in execute_command
    return self._execute_command(*args, **options)
  File "/home/labs/frappe-bench/env/lib/python3.10/site-packages/redis/client.py", line 565, in _execute_command
    conn = self.connection or pool.get_connection(command_name, **options)
  File "/home/labs/frappe-bench/env/lib/python3.10/site-packages/redis/connection.py", line 1422, in get_connection
    connection.connect()
  File "/home/labs/frappe-bench/env/lib/python3.10/site-packages/redis/connection.py", line 363, in connect
    raise ConnectionError(self._error_message(e))
redis.exceptions.ConnectionError: Error 111 connecting to 127.0.0.1:11000. Connection refused.
